Workbook

Sheet ALL
A2: NTUT VCP | B2: NVIDIA HOPPER H100, 16896 CUDA cores, clockspeed: 1590 MHz, FP64: 33.45 TFLOPS, 80GB VRAM (HBM3), PCIe 5
A3: NANO 5 | B3: NVIDIA HOPPER H100, 14592 CUDA cores, clockspeed: 1125 MHz, FP64: 25.61 TFLOPS, 80GB VRAM (HBM2e), PCIe 5 | I3: (NTD 50 /GPU.hr)
A4: TAIWANIA 2 | B4: NVIDIA TESLA V100, 5120 CUDA cores, clockspeed: 1230 MHz, FP64: 7.834 TFLOPS, 32GB VRAM (HBM2), PCIe 3 | I4: (NTD 21 /GPU.hr)
A5: GPU node09g | B5: NVIDIA RTX A6000 (Ampere), 10752 CUDA cores, clockspeed: 1410 MHz, FP64: 604.8 GFLOPS, 48GB VRAM (GDDR6), PCIe 4
A6: GPU desktop PC | B6: NVIDIA RTX 3060, 3584 CUDA cores, clockspeed: 1320 MHz, FP64: 199.0 GFLOPS, 12GB VRAM (GDDR6), PCIe 4
A7: FORERUNNER1 (8x14c) | B7: INTEL Xeon Platinum 8480+ , 2x56 cores, clockspeed: 2000 MHz | H7: *1 process = 1 NUMA node | I7: (NTD 0.2 /core.hr)
A8: TAIWANIA 3 (2x28c) | B8: INTEL Xeon Platinum 8280 , 2x28 cores, clockspeed: 2700 MHz | H8: *1 process = 1 NUMA node | I8: (NTD 0.08 /core.hr)
A9: CPU node09g (32c) | B9: INTEL Xeon Gold 6426Y , 2x16 cores, clockspeed: 2500 MHz
A10: CPU node08 (2x24c) | B10: INTEL Xeon Gold 5318Y , 2x24 cores, clockspeed: 2100 MHz | H10: *1 process = 1 NUMA node
E12: Runtime 1 GPU | K12: Runtime 1 CPU | P12: Throughput
C13: # cells | D13: VRAM usage (GiB) | E13: NANO 5 (H100 HBM2e) | F13: NTUT VCP (H100 HBM3) | G13: TAIWANIA 2 (V100 HBM2) | H13: GPU node09g (RTX A6000) | I13: GPU desktop PC (RTX 3060) | J13: FORERUNNER1 (112c) | K13: FORERUNNER1 (8x14c) | L13: TAIWANIA 3 (2x28c) | M13: CPU node09g (@32c) | N13: CPU node08 (2x24c) | O13: NANO 5 (H100 HBM2e) | P13: NTUT VCP (H100 HBM3) | Q13: TAIWANIA 2 (V100 HBM2) | R13: GPU node09g (RTX A6000) | S13: GPU desktop PC (RTX 3060) | T13: FORERUNNER1 (112c) | U13: FORERUNNER1 (8x14c) | V13: TAIWANIA 3 (2x28c) | W13: CPU node09g (@32c) | X13: CPU node08 (2x24c)
B14: 1M | C14: =0.9936*1000000 -> 993600 | D14: 0.906 | E14: 51.483462 | F14: 48.170766 | G14: 124.60779 | H14: 209.81018 | I14: 459.44869 | J14: 349.12871 | K14: 62.66125 | L14: 180.22743 | M14: 225.63301 | N14: 210.11817 | O14: =C14/E14 -> 19299.402 | P14: =C14/F14 -> 20626.618 | Q14: =C14/G14 -> 7973.8194 | R14: =C14/H14 -> 4735.7092 | S14: =C14/I14 -> 2162.5919 | T14: =C14/J14 -> 2845.9418 | U14: =C14/K14 -> 15856.69 | V14: =C14/L14 -> 5513.0341 | W14: =C14/M14 -> 4403.611 | X14: =C14/N14 -> 4728.7675 | Y14: 1M
B15: 2M | C15: =2.111984*1000000 -> 2111984 | D15: 1.296 | E15: 78.55414 | F15: 75.083887 | G15: 220.87542 | H15: 407.44582 | I15: 936.39152 | J15: 499.7374 | K15: 165.44382 | L15: 471.70797 | M15: 544.08545 | N15: 593.73761 | O15: =C15/E15 -> 26885.712 | P15: =C15/F15 -> 28128.325 | Q15: =C15/G15 -> 9561.8788 | R15: =C15/H15 -> 5183.472 | S15: =C15/I15 -> 2255.4497 | T15: =C15/J15 -> 4226.1876 | U15: =C15/K15 -> 12765.566 | V15: =C15/L15 -> 4477.3126 | W15: =C15/M15 -> 3881.7138 | X15: =C15/N15 -> 3557.0999 | Y15: 2M
B16: 4M | C16: =4.077216*1000000 -> 4077216 | D16: 1.932 | E16: 132.48448 | F16: 127.65115 | G16: 413.54868 | H16: 780.53182 | I16: 1830.0031 | J16: 1197.4907 | K16: 362.12415 | L16: 1143.8161 | M16: 1402.2771 | N16: 1569.1145 | O16: =C16/E16 -> 30775.045 | P16: =C16/F16 -> 31940.301 | Q16: =C16/G16 -> 9859.0956 | R16: =C16/H16 -> 5223.6384 | S16: =C16/I16 -> 2227.9831 | T16: =C16/J16 -> 3404.7997 | U16: =C16/K16 -> 11259.166 | V16: =C16/L16 -> 3564.5731 | W16: =C16/M16 -> 2907.5679 | X16: =C16/N16 -> 2598.4184 | Y16: 4M
B17: 8M | C17: =7.983668*1000000 -> 7983668 | D17: 3.212 | E17: 215.1346 | F17: 211.82235 | G17: 735.11478 | H17: 1451.2054 | I17: 3482.7156 | J17: 3273.2216 | K17: 894.25817 | L17: 2547.9857 | M17: 3423.004 | N17: 3230.012 | O17: =C17/E17 -> 37110.106 | P17: =C17/F17 -> 37690.394 | Q17: =C17/G17 -> 10860.437 | R17: =C17/H17 -> 5501.4046 | S17: =C17/I17 -> 2292.3686 | T17: =C17/J17 -> 2439.0857 | U17: =C17/K17 -> 8927.6993 | V17: =C17/L17 -> 3133.3253 | W17: =C17/M17 -> 2332.3572 | X17: =C17/N17 -> 2471.7147 | Y17: 8M
B18: 16M | C18: =16.09512*1000000 -> 16095120 | D18: 5.852 | E18: 429.13428 | F18: 425.11805 | G18: 1490.2234 | H18: 2960.6217 | I18: 7195.2647 | J18: 7977.4408 | K18: 2299.4936 | L18: 5575.0829 | M18: 6853.3531 | N18: 7543.1678 | O18: =C18/E18 -> 37506.023 | P18: =C18/F18 -> 37860.355 | Q18: =C18/G18 -> 10800.474 | R18: =C18/H18 -> 5436.3986 | S18: =C18/I18 -> 2236.9045 | T18: =C18/J18 -> 2017.5794 | U18: =C18/K18 -> 6999.4194 | V18: =C18/L18 -> 2886.9741 | W18: =C18/M18 -> 2348.503 | X18: =C18/N18 -> 2133.7349 | Y18: 16M
B19: 24M | C19: =24.0394*1000000 -> 24039400 | D19: 8.422 | E19: 627.92927 | F19: 623.52995 | G19: 2271.4019 | H19: 4465.3285 | I19: 11082.548 | J19: 13393.548 | K19: 3931.5298 | L19: 8339.7361 | M19: =104.768041299*100 -> 10476.804 | N19: 11802.881 | O19: =C19/E19 -> 38283.611 | P19: =C19/F19 -> 38553.721 | Q19: =C19/G19 -> 10583.508 | R19: =C19/H19 -> 5383.5681 | S19: =C19/I19 -> 2169.1221 | T19: =C19/J19 -> 1794.8493 | U19: =C19/K19 -> 6114.5155 | V19: =C19/L19 -> 2882.5133 | W19: =C19/M19 -> 2294.5356 | X19: =C19/N19 -> 2036.74 | Y19: 24M
B20: 32M | C20: =32.202144*1000000 -> 32202144 | D20: 11.014 | E20: 842.58005 | F20: 832.00245 | G20: 3003.347 | H20: 5950.4642 | I20: 14848.74 | J20: 19011.753 | K20: 5568.994 | L20: 11411.25 | M20: =1422.961865736*10 -> 14229.619 | N20: 16077.26 | O20: =C20/E20 -> 38218.498 | P20: =C20/F20 -> 38704.386 | Q20: =C20/G20 -> 10722.086 | R20: =C20/H20 -> 5411.7029 | S20: =C20/I20 -> 2168.6786 | T20: =C20/J20 -> 1693.802 | U20: =C20/K20 -> 5782.3988 | V20: =C20/L20 -> 2821.9646 | W20: =C20/M20 -> 2263.0363 | X20: =C20/N20 -> 2002.9622 | Y20: 32M
B21: 64M | C21: =63.78*1000000 -> 63780000 | D21: 20.62 | E21: 1601.0574 | F21: 1582.1923 | G21: 6538.2781 | H21: 12538.462 | J21: 36275.407 | K21: 11992.763 | L21: 22952.551 | M21: =30.585728795*1000 -> 30585.729 | N21: 34384.548 | O21: =C21/E21 -> 39836.174 | P21: =C21/F21 -> 40311.157 | Q21: =C21/G21 -> 9754.862 | R21: =C21/H21 -> 5086.7484 | T21: =C21/J21 -> 1758.216 | U21: =C21/K21 -> 5318.2073 | V21: =C21/L21 -> 2778.7761 | W21: =C21/M21 -> 2085.2863 | X21: =C21/N21 -> 1854.903 | Y21: 64M
B22: 128M | C22: =128.392704*1000000 -> 128392704 | D22: 40.72 | E22: 3531.4866 | F22: 3499.6662 | H22: =300.731087946*100 -> 30073.109 | J22: 86123.437 | K22: 24418.298 | L22: 47112.272 | M22: =76.9436751199999*1000 -> 76943.675 | N22: 94524.82 | O22: =C22/E22 -> 36356.56 | P22: =C22/F22 -> 36687.128 | R22: =C22/H22 -> 4269.3526 | T22: =C22/J22 -> 1490.7986 | U22: =C22/K22 -> 5258.053 | V22: =C22/L22 -> 2725.2497 | W22: =C22/M22 -> 1668.6583 | X22: =C22/N22 -> 1358.2962 | Y22: 128M
F65: choose left
F66: choose right
E67: Speed factor
E68: N5:TW2(x1) | F68: N5:F1(x1) | G68: N5:TW3(x1) | H68: TW2:F1(x1) | I68: TW2:TW3(x1) | J68: F1:TW3(x1)
D69: Cost factor: | E69: =50/21 -> 2.3809524 | F69: =50/(0.2*112) -> 2.2321429 | G69: =50/(0.08*56) -> 11.160714 | H69: =21/(0.2*112) -> 0.9375 | I69: =21/(0.08*56) -> 4.6875 | J69: =(0.2*112)/(0.08*56) -> 5
D70: 1M | E70: =O14/Q14 -> 2.420346 | F70: =O14/U14 -> 1.2171142 | G70: =O14/V14 -> 3.500686 | H70: =Q14/U14 -> 0.50286785 | I70: =Q14/V14 -> 1.4463577 | J70: =U14/V14 -> 2.8762183
D71: 2M | E71: =O15/Q15 -> 2.8117604 | F71: =O15/U15 -> 2.106112 | G71: =O15/V15 -> 6.0048772 | H71: =Q15/U15 -> 0.74903681 | I71: =Q15/V15 -> 2.1356291 | J71: =U15/V15 -> 2.851167
D72: 4M | E72: =O16/Q16 -> 3.1214877 | F72: =O16/U16 -> 2.7333325 | G72: =O16/V16 -> 8.6335852 | H72: =Q16/U16 -> 0.87565058 | I72: =Q16/V16 -> 2.7658559 | J72: =U16/V16 -> 3.1586297
D73: 8M | E73: =O17/Q17 -> 3.4169992 | F73: =O17/U17 -> 4.1567379 | G73: =O17/V17 -> 11.843681 | H73: =Q17/U17 -> 1.2164878 | I73: =Q17/V17 -> 3.4661059 | J73: =U17/V17 -> 2.8492731
D74: 16M | E74: =O18/Q18 -> 3.4726273 | F74: =O18/U18 -> 5.3584477 | G74: =O18/V18 -> 12.991465 | H74: =Q18/U18 -> 1.5430529 | I74: =Q18/V18 -> 3.7411054 | J74: =U18/V18 -> 2.4244829
D75: 24M | E75: =O19/Q19 -> 3.6172894 | F75: =O19/U19 -> 6.261103 | G75: =O19/V19 -> 13.28133 | H75: =Q19/U19 -> 1.7308825 | I75: =Q19/V19 -> 3.671625 | J75: =U19/V19 -> 2.1212445
D76: 32M | E76: =O20/Q20 -> 3.5644648 | F76: =O20/U20 -> 6.6094538 | G76: =O20/V20 -> 13.543224 | H76: =Q20/U20 -> 1.8542626 | I76: =Q20/V20 -> 3.7995111 | J76: =U20/V20 -> 2.0490685
D77: 64M | E77: =O21/Q21 -> 4.0837251 | F77: =O21/U21 -> 7.4905268 | G77: =O21/V21 -> 14.335871 | H77: =Q21/U21 -> 1.8342387 | I77: =Q21/V21 -> 3.5104887 | J77: =U21/V21 -> 1.9138668
D78: 128M | E78: =O22/Q22 -> #DIV/0! | F78: =O22/U22 -> 6.9144529 | G78: =O22/V22 -> 13.340635 | H78: =Q22/U22 -> 0 | I78: =Q22/V22 -> 0 | J78: =U22/V22 -> 1.929384
E81: N5:TW2(x2) | F81: N5:F1(x2) | G81: N5:TW3(x2) | H81: TW2:F1(x2) | I81: TW2:TW3(x2) | J81: F1:TW3(x2)
D82: Cost factor: | E82: =50/(21*2) -> 1.1904762 | F82: =50/(0.2*112*2) -> 1.1160714 | G82: =50/(0.08*56*2) -> 5.5803571 | H82: =21/(0.2*112*2) -> 0.46875 | I82: =21/(0.08*56*2) -> 2.34375 | J82: =(0.2*112)/(0.08*56*2) -> 2.5
D83: 1M | E83: =O14/'Taiwania 2'!I11 -> 2.067691 | F83: =O14/F1_multi!I11 -> #VALUE! | G83: =O14/TW3_multi!I11 -> 1.7016595 | H83: =Q14/F1_multi!I11 -> #VALUE! | I83: =Q14/TW3_multi!I11 -> 0.70306456 | J83: =U14/TW3_multi!I11 -> 1.39811
D84: 2M | E84: =O15/'Taiwania 2'!I12 -> 2.0480403 | F84: =O15/F1_multi!I12 -> 1.532871 | G84: =O15/TW3_multi!I12 -> 3.1124378 | H84: =Q15/F1_multi!I12 -> 0.54516415 | I84: =Q15/TW3_multi!I12 -> 1.1069356 | J84: =U15/TW3_multi!I12 -> 1.477812
D85: 4M | E85: =O16/'Taiwania 2'!I13 -> 2.0398027 | F85: =O16/F1_multi!I13 -> 1.4895628 | G85: =O16/TW3_multi!I13 -> 3.6850215 | H85: =Q16/F1_multi!I13 -> 0.47719643 | I85: =Q16/TW3_multi!I13 -> 1.1805337 | J85: =U16/TW3_multi!I13 -> 1.348179
D86: 8M | E86: =O17/'Taiwania 2'!I14 -> 2.0512218 | F86: =O17/F1_multi!I14 -> 1.8469685 | G86: =O17/TW3_multi!I14 -> 5.1643007 | H86: =Q17/F1_multi!I14 -> 0.54052354 | I86: =Q17/TW3_multi!I14 -> 1.5113555 | J86: =U17/TW3_multi!I14 -> 1.2423927
...

Sheet Taiwania 2
A1: Simulation case: flow past a stationary cylinder at Re 3900 with a constant CFL = 0.1
A2: FIxed domain, constant mesh ratio in 3D
A3: Data collection starts at t*=300 to ensure a steady condition (steady = similar fluctuation pattern and number of P iterations per timestep between different #of mesh)
A4: Sampling data is the total runtime of first 20,000 timesteps after t*=300
A6: TAIWANIA 2 | C6: (NTD 21 /GPU.hr)
A7: GPU | B7: NVIDIA TESLA V100, 5120 CUDA cores, clockspeed: 1230 MHz, 32GB VRAM (HBM2), PCIe 3
D9: inter node | E9: inter node | F9: inter node | M9: Speedup | R9: cost ratio | W9: Effectiveness (speedup/cost)
C10: # cells | D10: runtime 1 GPU | E10: runtime 2 GPU | F10: runtime 4 GPU | G10: runtime 8 GPU | H10: 1 GPU | I10: 2 GPU | J10: 4 GPU | K10: 8 GPU | M10: 1 GPU | N10: 2 GPU | O10: 4 GPU | P10: 8 GPU | R10: 1 GPU | S10: 2 GPU | T10: 4 GPU | U10: 8 GPU | W10: 1 GPU | X10: 2 GPU | Y10: 4 GPU | Z10: 8 GPU
B11: 1M | C11: =0.9936*1000000 -> 993600 | D11: 124.60779 | E11: 106.45189 | F11: 87.415261 | G11: 76.626268 | H11: =C11/D11 -> 7973.8194 | I11: =C11/E11 -> 9333.7939 | J11: =C11/F11 -> 11366.436 | K11: =C11/G11 -> 12966.833 | M11: =D11/D11 -> 1 | N11: =D11/E11 -> 1.170555 | O11: =D11/F11 -> 1.4254695 | P11: =D11/G11 -> 1.6261759 | R11: =1/M11 -> 1 | S11: =2/N11 -> 1.7085913 | T11: =4/O11 -> 2.806093 | U11: =8/P11 -> 4.9195171 | W11: =M11/R11 -> 1 | X11: =N11/S11 -> 0.68509947 | Y11: =O11/T11 -> 0.50799083 | Z11: =P11/U11 -> 0.330556
B12: 2M | C12: =2.111984*1000000 -> 2111984 | D12: 220.87542 | E12: 160.88205 | F12: 117.94417 | G12: 95.05592 | H12: =C12/D12 -> 9561.8788 | I12: =C12/E12 -> 13127.531 | J12: =C12/F12 -> 17906.642 | K12: =C12/G12 -> 22218.332 | M12: =D12/D12 -> 1 | N12: =D12/E12 -> 1.3729028 | O12: =D12/F12 -> 1.8727117 | P12: =D12/G12 -> 2.3236367 | R12: =1/M12 -> 1 | S12: =2/N12 -> 1.4567673 | T12: =4/O12 -> 2.1359401 | U12: =8/P12 -> 3.4428791 | W12: =M12/R12 -> 1 | X12: =N12/S12 -> 0.94243112 | Y12: =O12/T12 -> 0.87676224 | Z12: =P12/U12 -> 0.67491091
B13: 4M | C13: =4.077216*1000000 -> 4077216 | D13: 413.54868 | E13: 270.2422 | F13: 184.5525 | G13: 132.28571 | H13: =C13/D13 -> 9859.0956 | I13: =C13/E13 -> 15087.266 | J13: =C13/F13 -> 22092.445 | K13: =C13/G13 -> 30821.289 | M13: =D13/D13 -> 1 | N13: =D13/E13 -> 1.5302891 | O13: =D13/F13 -> 2.2408186 | P13: =D13/G13 -> 3.1261781 | R13: =1/M13 -> 1 | S13: =2/N13 -> 1.3069426 | T13: =4/O13 -> 1.7850619 | U13: =8/P13 -> 2.5590353 | W13: =M13/R13 -> 1 | X13: =N13/S13 -> 1.1708923 | Y13: =O13/T13 -> 1.255317 | Z13: =P13/U13 -> 1.2216237
B14: 8M | C14: =7.983668*1000000 -> 7983668 | D14: 735.11478 | E14: 441.28879 | F14: 277.78891 | G14: 183.88863 | H14: =C14/D14 -> 10860.437 | I14: =C14/E14 -> 18091.708 | J14: =C14/F14 -> 28740.053 | K14: =C14/G14 -> 43415.779 | M14: =D14/D14 -> 1 | N14: =D14/E14 -> 1.6658361 | O14: =D14/F14 -> 2.6463071 | P14: =D14/G14 -> 3.9976087 | R14: =1/M14 -> 1 | S14: =2/N14 -> 1.2005983 | T14: =4/O14 -> 1.5115404 | U14: =8/P14 -> 2.0011964 | W14: =M14/R14 -> 1 | X14: =N14/S14 -> 1.3875049 | Y14: =O14/T14 -> 1.7507353 | Z14: =P14/U14 -> 1.9976094
B15: 16M | C15: =16.09512*1000000 -> 16095120 | D15: 1490.2234 | E15: 859.74968 | F15: 503.15157 | G15: 320.06764 | H15: =C15/D15 -> 10800.474 | I15: =C15/E15 -> 18720.705 | J15: =C15/F15 -> 31988.611 | K15: =C15/G15 -> 50286.621 | M15: =D15/D15 -> 1 | N15: =D15/E15 -> 1.7333224 | O15: =D15/F15 -> 2.9617784 | P15: =D15/G15 -> 4.6559641 | R15: =1/M15 -> 1 | S15: =2/N15 -> 1.1538534 | T15: =4/O15 -> 1.35054 | U15: =8/P15 -> 1.7182263 | W15: =M15/R15 -> 1 | X15: =N15/S15 -> 1.5022034 | Y15: =O15/T15 -> 2.1930328 | Z15: =P15/U15 -> 2.7097502
B16: 24M | C16: =24.0394*1000000 -> 24039400 | D16: 2271.4019 | E16: 1264.6727 | F16: 714.5188 | G16: 449.40081 | H16: =C16/D16 -> 10583.508 | I16: =C16/E16 -> 19008.396 | J16: =C16/F16 -> 33644.181 | K16: =C16/G16 -> 53492.115 | M16: =D16/D16 -> 1 | N16: =D16/E16 -> 1.7960393 | O16: =D16/F16 -> 3.1789253 | P16: =D16/G16 -> 5.0542897 | R16: =1/M16 -> 1 | S16: =2/N16 -> 1.1135614 | T16: =4/O16 -> 1.2582869 | U16: =8/P16 -> 1.5828139 | W16: =M16/R16 -> 1 | X16: =N16/S16 -> 1.6128785 | Y16: =O16/T16 -> 2.5263916 | Z16: =P16/U16 -> 3.1932306
B17: 32M | C17: =32.202144*1000000 -> 32202144 | D17: 3003.347 | E17: 1669.5539 | F17: 932.19642 | G17: 567.31145 | H17: =C17/D17 -> 10722.086 | I17: =C17/E17 -> 19287.873 | J17: =C17/F17 -> 34544.376 | K17: =C17/G17 -> 56762.725 | M17: =D17/D17 -> 1 | N17: =D17/E17 -> 1.7988919 | O17: =D17/F17 -> 3.2217963 | P17: =D17/G17 -> 5.2940002 | R17: =1/M17 -> 1 | S17: =2/N17 -> 1.1117956 | T17: =4/O17 -> 1.2415434 | U17: =8/P17 -> 1.5111446 | W17: =M17/R17 -> 1 | X17: =N17/S17 -> 1.6180059 | Y17: =O17/T17 -> 2.5949928 | Z17: =P17/U17 -> 3.5033048
B18: 64M | C18: =63.78*1000000 -> 63780000 | D18: 6538.2781 | E18: 3237.764 | F18: 1761.9968 | G18: 1054.9949 | H18: =C18/D18 -> 9754.862 | I18: =C18/E18 -> 19698.78 | J18: =C18/F18 -> 36197.569 | K18: =C18/G18 -> 60455.27 | M18: =D18/D18 -> 1 | N18: =D18/E18 -> 2.0193807 | O18: =D18/F18 -> 3.7107208 | P18: =D18/G18 -> 6.1974501 | R18: =1/M18 -> 1 | S18: =2/N18 -> 0.99040267 | T18: =4/O18 -> 1.0779577 | U18: =8/P18 -> 1.2908535 | W18: =M18/R18 -> 1 | X18: =N18/S18 -> 2.0389491 | Y18: =O18/T18 -> 3.4423622 | Z18: =P18/U18 -> 4.8010484
B19: 128M | C19: =128.392704*1000000 -> 128392704 | F19: 4319.4695 | G19: 2128.0102 | J19: =C19/F19 -> 29724.184 | K19: =C19/G19 -> 60334.629

Sheet Nano 5
A1: Simulation case: flow past a stationary cylinder at Re 3900 with a constant CFL = 0.1
A2: FIxed domain, constant mesh ratio in 3D
A3: Data collection starts at t*=300 to ensure a steady condition (steady = similar fluctuation pattern and number of P iterations per timestep between different #of mesh)
A4: Sampling data is the total runtime of first 20,000 timesteps after t*=300
A6: TAIWANIA NANO5 | C6: (NTD 50 /GPU.hr)
A7: GPU | B7: NVIDIA HOPPER H100, 14592 CUDA cores, clockspeed: 1125 MHz, 80GB VRAM (HBM2e), PCIe 5
E9: inter node | F9: intra node | G9: intra node | M9: Speedup | R9: cost ratio | W9: Effectiveness (speedup/cost)
C10: # cells | D10: runtime 1 GPU | E10: runtime 2 GPU | F10: runtime 4 GPU | G10: runtime 8 GPU | H10: 1 GPU | I10: 2 GPU | J10: 4 GPU | K10: 8 GPU | M10: 1 GPU | N10: 2 GPU | O10: 4 GPU | P10: 8 GPU | R10: 1 GPU | S10: 2 GPU | T10: 4 GPU | U10: 8 GPU | W10: 1 GPU | X10: 2 GPU | Y10: 4 GPU | Z10: 8 GPU
B11: 1M | C11: =0.9936*1000000 -> 993600 | D11: 51.483462 | E11: 66.186466 | F11: 56.64558 | G11: 55.742443 | H11: =C11/D11 -> 19299.402 | I11: =C11/E11 -> 15012.132 | J11: =C11/F11 -> 17540.645 | K11: =C11/G11 -> 17824.838 | M11: =D11/D11 -> 1 | N11: =D11/E11 -> 0.77785482 | O11: =D11/F11 -> 0.90886989 | P11: =D11/G11 -> 0.92359536 | R11: =1/M11 -> 1 | S11: =2/N11 -> 2.5711739 | T11: =4/O11 -> 4.40107 | U11: =8/P11 -> 8.6618019 | W11: =M11/R11 -> 1 | X11: =N11/S11 -> 0.30252906 | Y11: =O11/T11 -> 0.20651112 | Z11: =P11/U11 -> 0.10662855
B12: 2M | C12: =2.111984*1000000 -> 2111984 | D12: 78.55414 | E12: 74.491345 | F12: 64.215399 | G12: 60.448016 | H12: =C12/D12 -> 26885.712 | I12: =C12/E12 -> 28352.072 | J12: =C12/F12 -> 32889.058 | K12: =C12/G12 -> 34938.847 | M12: =D12/D12 -> 1 | N12: =D12/E12 -> 1.0545405 | O12: =D12/F12 -> 1.2232913 | P12: =D12/G12 -> 1.2995321 | R12: =1/M12 -> 1 | S12: =2/N12 -> 1.8965606 | T12: =4/O12 -> 3.2698671 | U12: =8/P12 -> 6.1560617 | W12: =M12/R12 -> 1 | X12: =N12/S12 -> 0.55602784 | Y12: =O12/T12 -> 0.37411041 | Z12: =P12/U12 -> 0.21109797
B13: 4M | C13: =4.077216*1000000 -> 4077216 | D13: 132.48448 | E13: 106.26433 | F13: 89.96077 | G13: 99.119023 | H13: =C13/D13 -> 30775.045 | I13: =C13/E13 -> 38368.624 | J13: =C13/F13 -> 45322.156 | K13: =C13/G13 -> 41134.546 | M13: =D13/D13 -> 1 | N13: =D13/E13 -> 1.2467447 | O13: =D13/F13 -> 1.4726918 | P13: =D13/G13 -> 1.3366202 | R13: =1/M13 -> 1 | S13: =2/N13 -> 1.6041777 | T13: =4/O13 -> 2.7161149 | U13: =8/P13 -> 5.9852457 | W13: =M13/R13 -> 1 | X13: =N13/S13 -> 0.77718612 | Y13: =O13/T13 -> 0.54220525 | Z13: =P13/U13 -> 0.22331918
B14: 8M | C14: =7.983668*1000000 -> 7983668 | D14: 215.1346 | E14: 158.13049 | F14: 115.87579 | G14: 100.44239 | H14: =C14/D14 -> 37110.106 | I14: =C14/E14 -> 50487.846 | J14: =C14/F14 -> 68898.501 | K14: =C14/G14 -> 79485.047 | M14: =D14/D14 -> 1 | N14: =D14/E14 -> 1.3604878 | O14: =D14/F14 -> 1.8565967 | P14: =D14/G14 -> 2.1418706 | R14: =1/M14 -> 1 | S14: =2/N14 -> 1.470061 | T14: =4/O14 -> 2.1544797 | U14: =8/P14 -> 3.7350528 | W14: =M14/R14 -> 1 | X14: =N14/S14 -> 0.92546351 | Y14: =O14/T14 -> 0.86173785 | Z14: =P14/U14 -> 0.57345123
B15: 16M | C15: =16.09512*1000000 -> 16095120 | D15: 429.13428 | E15: 279.43262 | F15: 187.91458 | G15: 145.82283 | H15: =C15/D15 -> 37506.023 | I15: =C15/E15 -> 57599.289 | J15: =C15/F15 -> 85651.259 | K15: =C15/G15 -> 110374.49 | M15: =D15/D15 -> 1 | N15: =D15/E15 -> 1.5357344 | O15: =D15/F15 -> 2.2836668 | P15: =D15/G15 -> 2.9428471 | R15: =1/M15 -> 1 | S15: =2/N15 -> 1.3023085 | T15: =4/O15 -> 1.751569 | U15: =8/P15 -> 2.7184559 | W15: =M15/R15 -> 1 | X15: =N15/S15 -> 1.17924 | Y15: =O15/T15 -> 1.3037835 | Z15: =P15/U15 -> 1.0825436
B16: 24M | C16: =24.0394*1000000 -> 24039400 | D16: 627.92927 | E16: 382.92762 | F16: 240.27729 | G16: 174.11883 | H16: =C16/D16 -> 38283.611 | I16: =C16/E16 -> 62777.922 | J16: =C16/F16 -> 100048.57 | K16: =C16/G16 -> 138063.18 | M16: =D16/D16 -> 1 | N16: =D16/E16 -> 1.6398119 | O16: =D16/F16 -> 2.6133526 | P16: =D16/G16 -> 3.606326 | R16: =1/M16 -> 1 | S16: =2/N16 -> 1.2196521 | T16: =4/O16 -> 1.530601 | U16: =8/P16 -> 2.2183242 | W16: =M16/R16 -> 1 | X16: =N16/S16 -> 1.3444916 | Y16: =O16/T16 -> 1.7074029 | Z16: =P16/U16 -> 1.6256984
B17: 32M | C17: =32.202144*1000000 -> 32202144 | D17: 842.58005 | E17: 488.66429 | F17: 299.97635 | G17: 206.20108 | H17: =C17/D17 -> 38218.498 | I17: =C17/E17 -> 65898.296 | J17: =C17/F17 -> 107348.94 | K17: =C17/G17 -> 156168.65 | M17: =D17/D17 -> 1 | N17: =D17/E17 -> 1.7242513 | O17: =D17/F17 -> 2.8088216 | P17: =D17/G17 -> 4.0862058 | R17: =1/M17 -> 1 | S17: =2/N17 -> 1.1599237 | T17: =4/O17 -> 1.4240847 | U17: =8/P17 -> 1.9578064 | W17: =M17/R17 -> 1 | X17: =N17/S17 -> 1.4865213 | Y17: =O17/T17 -> 1.9723697 | Z17: =P17/U17 -> 2.0871347
B18: 64M | C18: =63.78*1000000 -> 63780000 | D18: 1601.0574 | E18: 933.84217 | F18: 535.11399 | G18: 357.00805 | H18: =C18/D18 -> 39836.174 | I18: =C18/E18 -> 68298.479 | J18: =C18/F18 -> 119189.56 | K18: =C18/G18 -> 178651.43 | M18: =D18/D18 -> 1 | N18: =D18/E18 -> 1.7144839 | O18: =D18/F18 -> 2.9919931 | P18: =D18/G18 -> 4.4846534 | R18: =1/M18 -> 1 | S18: =2/N18 -> 1.1665318 | T18: =4/O18 -> 1.3369015 | U18: =8/P18 -> 1.7838614 | W18: =M18/R18 -> 1 | X18: =N18/S18 -> 1.4697275 | Y18: =O18/T18 -> 2.2380056 | Z18: =P18/U18 -> 2.5140145
B19: 128M | C19: =128.392704*1000000 -> 128392704 | D19: 3531.4866 | E19: 1713.2919 | F19: 1036.3073 | G19: 628.88922 | H19: =C19/D19 -> 36356.56 | I19: =C19/E19 -> 74939.189 | J19: =C19/F19 -> 123894.43 | K19: =C19/G19 -> 204157.9 | M19: =D19/D19 -> 1 | N19: =D19/E19 -> 2.0612288 | O19: =D19/F19 -> 3.40776 | P19: =D19/G19 -> 5.6154351 | R19: =1/M19 -> 1 | S19: =2/N19 -> 0.970295 | T19: =4/O19 -> 1.1737916 | U19: =8/P19 -> 1.4246447 | W19: =M19/R19 -> 1 | X19: =N19/S19 -> 2.1243321 | Y19: =O19/T19 -> 2.903207 | Z19: =P19/U19 -> 3.9416389
E22: intra node
E23: 56.695352
E24: 75.480019
E25: 108.22506
E26: 158.19091
E27: 281.38667
E28: 387.06
E29: 497.27847
E30: 949.70011
E31: 1718.9079
C46: runtime 2 GPU in 1 node | D46: runtime 2 GPU across node
B47: 1M | C47: 61.509464 | D47: 63.955261
B48: 2M | C48: 84.350588 | D48: 81.350066
B49: 4M | C49: 118.98665 | D49: 117.61868
B50: 8M | C50: 177.68693 | D50: 175.98055
B51: 16M | C51: 307.60015 | D51: 306.30671
B52: 24M | C52: 433.40963 | D52: 420.40938
B53: 32M | C53: 549.93433 | D53: 544.67562
B54: 64M | D54: 1055.9249

Sheet StrongScaling_24M
A2: FORERUNNER1 (@112c) | B2: INTEL Xeon Platinum 8480+ , 2x56 cores, clockspeed: 2000 MHz | F2: (NTD 0.2 /core.hr)
A3: TAIWANIA 3 (@56c) | B3: INTEL Xeon Platinum 8280 , 2x28 cores, clockspeed: 2700 MHz | F3: (NTD 0.08 /core.hr)
C6: FORERUNNER 1 | G6: TAIWANIA 3
C7: runtime | D7: speedup | G7: runtime | H7: speedup
B8: 1 | C8: 2129.3481 | D8: =$C$8/C8 -> 1 | F8: 1 | G8: 2581.3325 | H8: =$G$8/G8 -> 1
B9: 2 | C9: 1005.0357 | D9: =$C$8/C9 -> 2.1186789 | F9: 2 | G9: 845.45164 | H9: =$G$8/G9 -> 3.0531995
B10: 4 | C10: 427.71799 | D10: =$C$8/C10 -> 4.9783926 | F10: 4 | G10: 559.67897 | H10: =$G$8/G10 -> 4.6121663
B11: 8 | C11: 275.9298 | D11: =$C$8/C11 -> 7.716992 | F11: 8 | G11: 329.22097 | H11: =$G$8/G11 -> 7.8407293
B12: 14 | C12: 238.34682 | D12: =$C$8/C12 -> 8.9338222 | F12: 14 | G12: 152.87395 | H12: =$G$8/G12 -> 16.885365
B13: 20 | C13: 160.7597 | D13: =$C$8/C13 -> 13.245534 | F13: 20 | G13: 188.06122 | H13: =$G$8/G13 -> 13.726022
B14: 28 | C14: 156.15247 | D14: =$C$8/C14 -> 13.636339 | F14: 28 | G14: 124.80618 | H14: =$G$8/G14 -> 20.682729
B15: 42 | C15: 106.11746 | D15: =$C$8/C15 -> 20.065954 | F15: 42 | G15: 116.54303 | H15: =$G$8/G15 -> 22.14918
B16: 56 | C16: 88.864695 | D16: =$C$8/C16 -> 23.961688 | F16: 56 | G16: 83.828559 | H16: =$G$8/G16 -> 30.792996
B17: 70 | C17: 64.846069 | D17: =$C$8/C17 -> 32.836965
B18: 84 | C18: 53.951904 | D18: =$C$8/C18 -> 39.467524
B19: 98 | C19: 45.644193 | D19: =$C$8/C19 -> 46.651018
B20: 112 | C20: 42.364985 | D20: =$C$8/C20 -> 50.261981
B21: *1 process = 1 NUMA node | F21: *1 process = 1 NUMA node

Sheet F1_multi
A1: Simulation case: flow past a stationary cylinder at Re 3900 with a constant CFL = 0.1
A2: FIxed domain, constant mesh ratio in 3D
A3: Data collection starts at t*=300 to ensure a steady condition (steady = similar fluctuation pattern and number of P iterations per timestep between different #of mesh)
A4: Sampling data is the total runtime of first 20,000 timesteps after t*=300
A6: FORERUNNER1 (@112c) | B6: INTEL Xeon Platinum 8480+ , 2x56 cores, clockspeed: 2000 MHz | F6: (NTD 0.2 /core.hr)
M9: Speedup | R9: cost ratio | W9: Effectiveness (speedup/cost)
C10: # cells | D10: runtime 1 NODE | E10: runtime 2 NODE | F10: runtime 4 NODE | G10: runtime 8 NODE | H10: 1 NODE | I10: 2 NODE | J10: 4 NODE | K10: 8 NODE | M10: 1 NODE | N10: 2 NODE | O10: 4 NODE | P10: 8 NODE | R10: 1 NODE | S10: 2 NODE | T10: 4 NODE | U10: 8 NODE | W10: 1 NODE | X10: 2 NODE | Y10: 4 NODE | Z10: 8 NODE
B11: 1M | C11: =0.9936*1000000 -> 993600 | D11: 62.66125 | E11: Diverged | F11: Diverged | G11: Diverged | H11: =C11/D11 -> 15856.69 | I11: =C11/E11 -> #VALUE! | J11: =C11/F11 -> #VALUE! | K11: =C11/G11 -> #VALUE! | M11: =D11/D11 -> 1 | N11: =D11/E11 -> #VALUE! | O11: =D11/F11 -> #VALUE! | P11: =D11/G11 -> #VALUE! | R11: =1/M11 -> 1 | S11: =2/N11 -> #VALUE! | T11: =4/O11 -> #VALUE! | U11: =8/P11 -> #VALUE! | W11: =M11/R11 -> 1 | X11: =N11/S11 -> #VALUE! | Y11: =O11/T11 -> #VALUE! | Z11: =P11/U11 -> #VALUE!
B12: 2M | C12: =2.111984*1000000 -> 2111984 | D12: 165.44382 | E12: 120.41336 | F12: Diverged | G12: Diverged | H12: =C12/D12 -> 12765.566 | I12: =C12/E12 -> 17539.449 | J12: =C12/F12 -> #VALUE! | K12: =C12/G12 -> #VALUE! | M12: =D12/D12 -> 1 | N12: =D12/E12 -> 1.3739656 | O12: =D12/F12 -> #VALUE! | P12: =D12/G12 -> #VALUE! | R12: =1/M12 -> 1 | S12: =2/N12 -> 1.4556405 | T12: =4/O12 -> #VALUE! | U12: =8/P12 -> #VALUE! | W12: =M12/R12 -> 1 | X12: =N12/S12 -> 0.94389078 | Y12: =O12/T12 -> #VALUE! | Z12: =P12/U12 -> #VALUE!
B13: 4M | C13: =4.077216*1000000 -> 4077216 | D13: 362.12415 | E13: 197.34396 | F13: Diverged | G13: Diverged | H13: =C13/D13 -> 11259.166 | I13: =C13/E13 -> 20660.455 | J13: =C13/F13 -> #VALUE! | K13: =C13/G13 -> #VALUE! | M13: =D13/D13 -> 1 | N13: =D13/E13 -> 1.8349898 | O13: =D13/F13 -> #VALUE! | P13: =D13/G13 -> #VALUE! | R13: =1/M13 -> 1 | S13: =2/N13 -> 1.0899243 | T13: =4/O13 -> #VALUE! | U13: =8/P13 -> #VALUE! | W13: =M13/R13 -> 1 | X13: =N13/S13 -> 1.6835938 | Y13: =O13/T13 -> #VALUE! | Z13: =P13/U13 -> #VALUE!
B14: 8M | C14: =7.983668*1000000 -> 7983668 | D14: 894.25817 | E14: 397.34684 | F14: 295.25413 | G14: Diverged | H14: =C14/D14 -> 8927.6993 | I14: =C14/E14 -> 20092.441 | J14: =C14/F14 -> 27039.987 | K14: =C14/G14 -> #VALUE! | M14: =D14/D14 -> 1 | N14: =D14/E14 -> 2.2505732 | O14: =D14/F14 -> 3.0287744 | P14: =D14/G14 -> #VALUE! | R14: =1/M14 -> 1 | S14: =2/N14 -> 0.88866249 | T14: =4/O14 -> 1.3206662 | U14: =8/P14 -> #VALUE! | W14: =M14/R14 -> 1 | X14: =N14/S14 -> 2.5325399 | Y14: =O14/T14 -> 2.2933686 | Z14: =P14/U14 -> #VALUE!
B15: 16M | C15: =16.09512*1000000 -> 16095120 | D15: 2299.4936 | E15: 1125.2187 | F15: 511.64875 | G15: Diverged | H15: =C15/D15 -> 6999.4194 | I15: =C15/E15 -> 14303.993 | J15: =C15/F15 -> 31457.362 | K15: =C15/G15 -> #VALUE! | M15: =D15/D15 -> 1 | N15: =D15/E15 -> 2.043597 | O15: =D15/F15 -> 4.4942816 | P15: =D15/G15 -> #VALUE! | R15: =1/M15 -> 1 | S15: =2/N15 -> 0.97866653 | T15: =4/O15 -> 0.89001989 | U15: =8/P15 -> #VALUE! | W15: =M15/R15 -> 1 | X15: =N15/S15 -> 2.0881444 | Y15: =O15/T15 -> 5.0496418 | Z15: =P15/U15 -> #VALUE!
B16: 24M | C16: =24.0394*1000000 -> 24039400 | D16: 3931.5298 | E16: 1768.2484 | F16: 869.34775 | G16: Diverged | H16: =C16/D16 -> 6114.5155 | I16: =C16/E16 -> 13595.036 | J16: =C16/F16 -> 27652.226 | K16: =C16/G16 -> #VALUE! | M16: =D16/D16 -> 1 | N16: =D16/E16 -> 2.2234036 | O16: =D16/F16 -> 4.5223903 | P16: =D16/G16 -> #VALUE! | R16: =1/M16 -> 1 | S16: =2/N16 -> 0.8995218 | T16: =4/O16 -> 0.88448801 | U16: =8/P16 -> #VALUE! | W16: =M16/R16 -> 1 | X16: =N16/S16 -> 2.4717618 | Y16: =O16/T16 -> 5.1130035 | Z16: =P16/U16 -> #VALUE!
B17: 32M | C17: =32.202144*1000000 -> 32202144 | D17: 5568.994 | E17: 2416.7629 | F17: 1354.5031 | G17: Diverged | H17: =C17/D17 -> 5782.3988 | I17: =C17/E17 -> 13324.495 | J17: =C17/F17 -> 23774.139 | K17: =C17/G17 -> #VALUE! | M17: =D17/D17 -> 1 | N17: =D17/E17 -> 2.3043196 | O17: =D17/F17 -> 4.1114665 | P17: =D17/G17 -> #VALUE! | R17: =1/M17 -> 1 | S17: =2/N17 -> 0.86793518 | T17: =4/O17 -> 0.97288887 | U17: =8/P17 -> #VALUE! | W17: =M17/R17 -> 1 | X17: =N17/S17 -> 2.6549443 | Y17: =O17/T17 -> 4.2260392 | Z17: =P17/U17 -> #VALUE!
B18: 64M | C18: =63.78*1000000 -> 63780000 | D18: 11992.763 | E18: 5936.1629 | F18: 3175.0545 | G18: Diverged | H18: =C18/D18 -> 5318.2073 | I18: =C18/E18 -> 10744.314 | J18: =C18/F18 -> 20087.844 | K18: =C18/G18 -> #VALUE! | M18: =D18/D18 -> 1 | N18: =D18/E18 -> 2.0202887 | O18: =D18/F18 -> 3.7771834 | P18: =D18/G18 -> #VALUE! | R18: =1/M18 -> 1 | S18: =2/N18 -> 0.98995751 | T18: =4/O18 -> 1.0589902 | U18: =8/P18 -> #VALUE! | W18: =M18/R18 -> 1 | X18: =N18/S18 -> 2.0407833 | Y18: =O18/T18 -> 3.5667786 | Z18: =P18/U18 -> #VALUE!
B19: 128M | C19: =128.392704*1000000 -> 128392704 | D19: 24418.298 | E19: 12502.971 | F19: 6613.6037 | G19: Diverged | H19: =C19/D19 -> 5258.053 | I19: =C19/E19 -> 10268.976 | J19: =C19/F19 -> 19413.426 | K19: =C19/G19 -> #VALUE! | M19: =D19/D19 -> 1 | N19: =D19/E19 -> 1.9529997 | O19: =D19/F19 -> 3.692132 | P19: =D19/G19 -> #VALUE! | R19: =1/M19 -> 1 | S19: =2/N19 -> 1.0240657 | T19: =4/O19 -> 1.0833849 | U19: =8/P19 -> #VALUE! | W19: =M19/R19 -> 1 | X19: =N19/S19 -> 1.9071038 | Y19: =O19/T19 -> 3.4079597 | Z19: =P19/U19 -> #VALUE!

Sheet TW3_multi
A1: Simulation case: flow past a stationary cylinder at Re 3900 with a constant CFL = 0.1
A2: FIxed domain, constant mesh ratio in 3D
A3: Data collection starts at t*=300 to ensure a steady condition (steady = similar fluctuation pattern and number of P iterations per timestep between different #of mesh)
A4: Sampling data is the total runtime of first 20,000 timesteps after t*=300
A6: TAIWANIA 3 (2x28c) | B6: INTEL Xeon Platinum 8280 , 2x28 cores, clockspeed: 2700 MHz | F6: (NTD 0.08 /core.hr)
M9: Speedup | R9: cost ratio | W9: Effectiveness (speedup/cost)
C10: # cells | D10: runtime 1 NODE | E10: runtime 2 NODE | F10: runtime 4 NODE | G10: runtime 8 NODE | H10: 1 NODE | I10: 2 NODE | J10: 4 NODE | K10: 8 NODE | M10: 1 NODE | N10: 2 NODE | O10: 4 NODE | P10: 8 NODE | R10: 1 NODE | S10: 2 NODE | T10: 4 NODE | U10: 8 NODE | W10: 1 NODE | X10: 2 NODE | Y10: 4 NODE | Z10: 8 NODE
B11: 1M | C11: =0.9936*1000000 -> 993600 | D11: 180.22743 | E11: 87.60732 | F11: 64.733452 | G11: Diverged | H11: =C11/D11 -> 5513.0341 | I11: =C11/E11 -> 11341.518 | J11: =C11/F11 -> 15349.096 | K11: =C11/G11 -> #VALUE! | M11: =D11/D11 -> 1 | N11: =D11/E11 -> 2.0572189 | O11: =D11/F11 -> 2.7841468 | P11: =D11/G11 -> #VALUE! | R11: =1/M11 -> 1 | S11: =2/N11 -> 0.97218628 | T11: =4/O11 -> 1.4367058 | U11: =8/P11 -> #VALUE! | W11: =M11/R11 -> 1 | X11: =N11/S11 -> 2.1160748 | Y11: =O11/T11 -> 1.9378684 | Z11: =P11/U11 -> #VALUE!
B12: 2M | C12: =2.111984*1000000 -> 2111984 | D12: 471.70797 | E12: 244.49487 | F12: 123.15066 | G12: 92.475982 | H12: =C12/D12 -> 4477.3126 | I12: =C12/E12 -> 8638.1525 | J12: =C12/F12 -> 17149.596 | K12: =C12/G12 -> 22838.189 | M12: =D12/D12 -> 1 | N12: =D12/E12 -> 1.9293164 | O12: =D12/F12 -> 3.8303324 | P12: =D12/G12 -> 5.10087 | R12: =1/M12 -> 1 | S12: =2/N12 -> 1.0366366 | T12: =4/O12 -> 1.0442958 | U12: =8/P12 -> 1.5683599 | W12: =M12/R12 -> 1 | X12: =N12/S12 -> 1.8611309 | Y12: =O12/T12 -> 3.6678617 | Z12: =P12/U12 -> 3.2523594
B13: 4M | C13: =4.077216*1000000 -> 4077216 | D13: 1143.8161 | E13: 488.20817 | F13: 237.16421 | G13: 150.1579 | H13: =C13/D13 -> 3564.5731 | I13: =C13/E13 -> 8351.3884 | J13: =C13/F13 -> 17191.532 | K13: =C13/G13 -> 27152.857 | M13: =D13/D13 -> 1 | N13: =D13/E13 -> 2.342886 | O13: =D13/F13 -> 4.8228866 | P13: =D13/G13 -> 7.617422 | R13: =1/M13 -> 1 | S13: =2/N13 -> 0.85364802 | T13: =4/O13 -> 0.82937882 | U13: =8/P13 -> 1.0502241 | W13: =M13/R13 -> 1 | X13: =N13/S13 -> 2.7445574 | Y13: =O13/T13 -> 5.8150588 | Z13: =P13/U13 -> 7.2531398
B14: 8M | C14: =7.983668*1000000 -> 7983668 | D14: 2547.9857 | E14: 1111.0198 | F14: 517.1804 | G14: 308.98412 | H14: =C14/D14 -> 3133.3253 | I14: =C14/E14 -> 7185.8918 | J14: =C14/F14 -> 15436.912 | K14: =C14/G14 -> 25838.441 | M14: =D14/D14 -> 1 | N14: =D14/E14 -> 2.2933756 | O14: =D14/F14 -> 4.9266865 | P14: =D14/G14 -> 8.2463322 | R14: =1/M14 -> 1 | S14: =2/N14 -> 0.87207694 | T14: =4/O14 -> 0.81190471 | U14: =8/P14 -> 0.97012827 | W14: =M14/R14 -> 1 | X14: =N14/S14 -> 2.6297859 | Y14: =O14/T14 -> 6.0680601 | Z14: =P14/U14 -> 8.5002494
B15: 16M | C15: =16.09512*1000000 -> 16095120 | D15: 5575.0829 | E15: 2847.2384 | F15: 1294.7319 | G15: 649.88592 | H15: =C15/D15 -> 2886.9741 | I15: =C15/E15 -> 5652.8881 | J15: =C15/F15 -> 12431.238 | K15: =C15/G15 -> 24766.07 | M15: =D15/D15 -> 1 | N15: =D15/E15 -> 1.9580668 | O15: =D15/F15 -> 4.3059747 | P15: =D15/G15 -> 8.5785562 | R15: =1/M15 -> 1 | S15: =2/N15 -> 1.0214156 | T15: =4/O15 -> 0.92894182 | U15: =8/P15 -> 0.93255786 | W15: =M15/R15 -> 1 | X15: =N15/S15 -> 1.9170128 | Y15: =O15/T15 -> 4.6353546 | Z15: =P15/U15 -> 9.1989532
B16: 24M | C16: =24.0394*1000000 -> 24039400 | D16: 8339.7361 | E16: 4272.0728 | F16: 1997.8013 | G16: 1042.0168 | H16: =C16/D16 -> 2882.5133 | I16: =C16/E16 -> 5627.1044 | J16: =C16/F16 -> 12032.929 | K16: =C16/G16 -> 23070.069 | M16: =D16/D16 -> 1 | N16: =D16/E16 -> 1.9521521 | O16: =D16/F16 -> 4.1744573 | P16: =D16/G16 -> 8.0034561 | R16: =1/M16 -> 1 | S16: =2/N16 -> 1.0245103 | T16: =4/O16 -> 0.95820839 | U16: =8/P16 -> 0.99956817 | W16: =M16/R16 -> 1 | X16: =N16/S16 -> 1.9054489 | Y16: =O16/T16 -> 4.3565234 | Z16: =P16/U16 -> 8.0069137
B17: 32M | C17: =32.202144*1000000 -> 32202144 | D17: 11411.25 | E17: 5745.3572 | F17: 2766.8314 | G17: 1464.0141 | H17: =C17/D17 -> 2821.9646 | I17: =C17/E17 -> 5604.8985 | J17: =C17/F17 -> 11638.636 | K17: =C17/G17 -> 21995.788 | M17: =D17/D17 -> 1 | N17: =D17/E17 -> 1.9861689 | O17: =D17/F17 -> 4.1243027 | P17: =D17/G17 -> 7.7944947 | R17: =1/M17 -> 1 | S17: =2/N17 -> 1.0069637 | T17: =4/O17 -> 0.96986092 | U17: =8/P17 -> 1.0263654 | W17: =M17/R17 -> 1 | X17: =N17/S17 -> 1.9724335 | Y17: =O17/T17 -> 4.2524682 | Z17: =P17/U17 -> 7.5942685
B18: 64M | C18: =63.78*1000000 -> 63780000 | D18: 22952.551 | E18: 12409.337 | F18: 6307.1351 | G18: 3332.1876 | H18: =C18/D18 -> 2778.7761 | I18: =C18/E18 -> 5139.6785 | J18: =C18/F18 -> 10112.357 | K18: =C18/G18 -> 19140.579 | M18: =D18/D18 -> 1 | N18: =D18/E18 -> 1.8496195 | O18: =D18/F18 -> 3.6391405 | P18: =D18/G18 -> 6.888133 | R18: =1/M18 -> 1 | S18: =2/N18 -> 1.0813035 | T18: =4/O18 -> 1.0991606 | U18: =8/P18 -> 1.1614178 | W18: =M18/R18 -> 1 | X18: =N18/S18 -> 1.7105462 | Y18: =O18/T18 -> 3.310836 | Z18: =P18/U18 -> 5.9307971
B19: 128M | C19: =128.392704*1000000 -> 128392704 | D19: 47112.272 | E19: 23848.506 | F19: 12517.492 | G19: 6621.7976 | H19: =C19/D19 -> 2725.2497 | I19: =C19/E19 -> 5383.6791 | J19: =C19/F19 -> 10257.063 | K19: =C19/G19 -> 19389.403 | M19: =D19/D19 -> 1 | N19: =D19/E19 -> 1.9754811 | O19: =D19/F19 -> 3.763715 | P19: =D19/G19 -> 7.1147254 | R19: =1/M19 -> 1 | S19: =2/N19 -> 1.0124116 | T19: =4/O19 -> 1.0627797 | U19: =8/P19 -> 1.1244285 | W19: =M19/R19 -> 1 | X19: =N19/S19 -> 1.9512627 | Y19: =O19/T19 -> 3.5413877 | Z19: =P19/U19 -> 6.3274147

Sheet node09g_CPU_16M
A2: CPU node09g (32c): | B2: INTEL Xeon Gold 6426Y , 2x16 cores, clockspeed: 3300 MHz
C6: runtime | D6: speedup | E6: ideal
B7: 1 | C7: 386.67029 | D7: =$C$7/C7 -> 1 | E7: =B7 -> 1
B8: 2 | C8: 213.9801 | D8: =$C$7/C8 -> 1.8070385 | E8: =B8 -> 2
B9: 4 | C9: 109.35244 | D9: =$C$7/C9 -> 3.5360006 | E9: =B9 -> 4
B10: 8 | C10: 60.095664 | D10: =$C$7/C10 -> 6.434246 | E10: =B10 -> 8
B11: 16 | C11: 41.770826 | D11: =$C$7/C11 -> 9.256946 | E11: =B11 -> 16
B12: 32 | C12: 36.782932 | D12: =$C$7/C12 -> 10.51222 | E12: =B12 -> 32

Sheet 0.994
A1: non-uniform-sin4 (Sin-Uniform) | F1: <-- input
J2: Re = | K2: 3900
A3: dySml = | B3: 0.017 | C3: dzSml = | D3: 0.017 | E3: dxSml = | F3: =D3*9 -> 0.153 | J3: nu = | K3: =K5/K2 -> 0.00025641026 | L3: (Uinf/Re for dimensionless)
A4: GridderYc = | B4: =B7/2 -> 12 | C4: GridderZc = | D4: 12.9 | E4: GridderXc = | F4: =B15/2 -> 1.5 | J4: fluid density = | K4: 1
J5: freestream vel = | K5: 1
A7: ly = | B7: 24 | C7: lySml = | D7: 1.53 | J7: Cf = | K7: =(2*LOG10(K2)-0.65)^-2.3 -> 0.013346704
A8: ny = | B8: =D8+F8+F9 -> 180 | C8: nySml = | D8: =D7/B3 -> 90 | E8: nyLrg1 = | F8: 45 | G8: <-- adjustable value | J8: tau = | K8: =0.5*K7*K4*K5^2 -> 0.0066733521
A9: nyLow = | B9: =F8 -> 45 | E9: nyLrg2 = | F9: 45 | G9: <-- adjustable value | J9: ufric = | K9: =SQRT(K8/K4) -> 0.081690588
A11: lz = | B11: 36 | C11: lzSml = | D11: 2.975 | J11: y+ = | K11: =(B3*K9)/K3 -> 5.416086
A12: nz = | B12: =D12+F13+F12 -> 276 | C12: nzSml = | D12: =D11/D3 -> 175 | E12: nzLrg1 = | F12: 45 | G12: <-- adjustable value | J12: fwall = | K12: =(1-EXP(-1*K11/25)) -> 0.19478297
A13: nzUps = | B13: =F12 -> 45 | E13: nzLrg2 = | F13: 56 | G13: <-- adjustable value
J14: Applied Dt = | K14: 0.0017
A15: lx = | B15: 3 | J15: CFL = | K15: =K14/B3 -> 0.1
A16: nx = | B16: =EVEN(B15/F3) -> 20
A18: Kuyper tune factor = | C18: 1
A20: highest ratio in y1 = | C20: =ROUND(MAX(F28:F528),3) -> 1.195 | G20: Number of cells (M) = | H20: =(B8*B12*B16)/1000000 -> 0.9936 | I20: 0.54
A21: highest ratio in y2 = | C21: =ROUND(MAX(C29:C529),3) -> 1.195
A22: highest ratio in z1 = | C22: =ROUND(MAX(M28:M528),3) -> 1.197
A23: highest ratio in z2 = | C23: =ROUND(MAX(J28:J528),3) -> 1.199
A25: y2 direction | D25: y1 direction (yLow) | H25: z2 direction | K25: z1 direction (zUps)
A26: H = | B26: =B7-(B4+D7*0.5) -> 11.235 | D26: H = | E26: =B4-D7*0.5 -> 11.235 | H26: H = | I26: =B11-(D4+D11*0.5) -> 21.6125 | K26: H = | L26: =D4-D11*0.5 -> 11.4125
A28: 0 | B28: =IF(A28=" "," ",($B$26-$B$3*($F$8/2))*((A28/($F$8/2))-($C$18/(PI()))*SIN((PI()*A28)/($F$8/2)))+$B$3*A28) -> 0 | D28: 0 | E28: =IF(D28=" "," ",($E$26-$B$3*($F$8))*((D28/($F$8))-($C$18/(PI()))*SIN((PI()*D28)/($F$8)))+$B$3*D28) -> 0 | H28: 0 | I28: =IF(H28=" "," ",($I$26-$D$3*$F$13)*((H28/$F$13)-($C$18/(PI()))*SIN((PI()*H28)/$F$13))+$D$3*H28) -> 0 | K28: 0 | L28: =IF(K28=" "," ",($I$26-$D$3*$F$13)*((K28/$F$13)-($C$18/(PI()))*SIN((PI()*K28)/$F$13))+$D$3*K28) -> 0
A29: =IF(($F$9)-ROW(A1)>=0,($F$9)-(($F$9)-ROW(A1))," ") -> 1 | B29: =IF(A29=" "," ",($B$26-$B$3*($F$9))*((A29/($F$9))-($C$18/(PI()))*SIN((PI()*A29)/($F$9)))+$B$3*A29) -> 0.017188952 | D29: =IF(($F$8)-ROW(D1)>=0,($F$8)-(($F$8)-ROW(D1))," ") -> 1 | E29: =IF(D29=" "," ",($E$26-$B$3*($F$8))*((D29/($F$8))-($C$18/(PI()))*SIN((PI()*D29)/($F$8)))+$B$3*D29) -> 0.017188952 | H29: =IF($F$13-ROW(H1)>=0,$F$13-($F$13-ROW(H1))," ") -> 1 | I29: =IF(H29=" "," ",($I$26-$D$3*$F$13)*((H29/$F$13)-($C$18/(PI()))*SIN((PI()*H29)/$F$13))+$D$3*H29) -> 0.017193489 | K29: =IF($F$12-ROW(K1)>=0,$F$12-($F$12-ROW(K1))," ") -> 1 | L29: =IF(K29=" "," ",($L$26-$D$3*$F$12)*((K29/$F$12)-($C$18/(PI()))*SIN((PI()*K29)/$F$12))+$D$3*K29) -> 0.017192155
A30: =IF(($F$9)-ROW(A2)>=0,($F$9)-(($F$9)-ROW(A2))," ") -> 2 | B30: =IF(A30=" "," ",($B$26-$B$3*($F$9))*((A30/($F$9))-($C$18/(PI()))*SIN((PI()*A30)/($F$9)))+$B$3*A30) -> 0.035510512 | C30: =IF(A30=" "," ",(B30-B29)/(B29-B28)) -> 1.0658916 | D30: =IF(($F$8)-ROW(D2)>=0,($F$8)-(($F$8)-ROW(D2))," ") -> 2 | E30: =IF(D30=" "," ",($E$26-$B$3*($F$8))*((D30/($F$8))-($C$18/(PI()))*SIN((PI()*D30)/($F$8)))+$B$3*D30) -> 0.035510512 | F30: =IF(D30=" "," ",(E30-E29)/(E29-E28)) -> 1.0658916 | H30: =IF($F$13-ROW(H2)>=0,$F$13-($F$13-ROW(H2))," ") -> 2 | I30: =IF(H30=" "," ",($I$26-$D$3*$F$13)*((H30/$F$13)-($C$18/(PI()))*SIN((PI()*H30)/$F$13))+$D$3*H30) -> 0.035547184 | J30: =IF(H30=" "," ",(I30-I29)/(I29-I28)) -> 1.0674793 | K30: =IF($F$12-ROW(K2)>=0,$F$12-($F$12-ROW(K2))," ") -> 2 | L30: =IF(K30=" "," ",($L$26-$D$3*$F$12)*((K30/$F$12)-($C$18/(PI()))*SIN((PI()*K30)/$F$12))+$D$3*K30) -> 0.03553612 | M30: =IF(K30=" "," ",(L30-L29)/(L29-L28)) -> 1.0669962
A31: =IF(($F$9)-ROW(A3)>=0,($F$9)-(($F$9)-ROW(A3))," ") -> 3 | B31: =IF(A31=" "," ",($B$26-$B$3*($F$9))*((A31/($F$9))-($C$18/(PI()))*SIN((PI()*A31)/($F$9)))+$B$3*A31) -> 0.056091771 | C31: =IF(A31=" "," ",(B31-B30)/(B30-B29)) -> 1.1233355 | D31: =IF(($F$8)-ROW(D3)>=0,($F$8)-(($F$8)-ROW(D3))," ") -> 3 | E31: =IF(D31=" "," ",($E$26-$B$3*($F$8))*((D31/($F$8))-($C$18/(PI()))*SIN((PI()*D31)/($F$8)))+$B$3*D31) -> 0.056091771 | F31: =IF(D31=" "," ",(E31-E30)/(E30-E29)) -> 1.1233355 | H31: =IF($F$13-ROW(H3)>=0,$F$13-($F$13-ROW(H3))," ") -> 3 | I31: =IF(H31=" "," ",($I$26-$D$3*$F$13)*((H31/$F$13)-($C$18/(PI()))*SIN((PI()*H31)/$F$13))+$D$3*H31) -> 0.056217638 | J31: =IF(H31=" "," ",(I31-I30)/(I30-I29)) -> 1.1262285 | K31: =IF($F$12-ROW(K3)>=0,$F$12-($F$12-ROW(K3))," ") -> 3 | L31: =IF(K31=" "," ",($L$26-$D$3*$F$12)*((K31/$F$12)-($C$18/(PI()))*SIN((PI()*K31)/$F$12))+$D$3*K31) -> 0.056178092 | M31: =IF(K31=" "," ",(L31-L30)/(L30-L29)) -> 1.1252732
A32: =IF(($F$9)-ROW(A4)>=0,($F$9)-(($F$9)-ROW(A4))," ") -> 4 | B32: =IF(A32=" "," ",($B$26-$B$3*($F$9))*((A32/($F$9))-($C$18/(PI()))*SIN((PI()*A32)/($F$9)))+$B$3*A32) -> 0.080048808 | C32: =IF(A32=" "," ",(B32-B31)/(B31-B30)) -> 1.164022 | D32: =IF(($F$8)-ROW(D4)>=0,($F$8)-(($F$8)-ROW(D4))," ") -> 4 | E32: =IF(D32=" "," ",($E$26-$B$3*($F$8))*((D32/($F$8))-($C$18/(PI()))*SIN((PI()*D32)/($F$8)))+$B$3*D32) -> 0.080048808 | F32: =IF(D32=" "," ",(E32-E31)/(E31-E30)) -> 1.164022 | H32: =IF($F$13-ROW(H4)>=0,$F$13-($F$13-ROW(H4))," ") -> 4 | I32: =IF(H32=" "," ",($I$26-$D$3*$F$13)*((H32/$F$13)-($C$18/(PI()))*SIN((PI()*H32)/$F$13))+$D$3*H32) -> 0.080354117 | J32: =IF(H32=" "," ",(I32-I31)/(I31-I30)) -> 1.1676802 | K32: =IF($F$12-ROW(K4)>=0,$F$12-($F$12-ROW(K4))," ") -> 4 | L32: =IF(K32=" "," ",($L$26-$D$3*$F$12)*((K32/$F$12)-($C$18/(PI()))*SIN((PI()*K32)/$F$12))+$D$3*K32) -> 0.080253074 | M32: =IF(K32=" "," ",(L32-L31)/(L31-L30)) -> 1.1663121
A33: =IF(($F$9)-ROW(A5)>=0,($F$9)-(($F$9)-ROW(A5))," ") -> 5 | B33: =IF(A33=" "," ",($B$26-$B$3*($F$9))*((A33/($F$9))-($C$18/(PI()))*SIN((PI()*A33)/($F$9)))+$B$3*A33) -> 0.10848126 | C33: =IF(A33=" "," ",(B33-B32)/(B32-B31)) -> 1.18681 | D33: =IF(($F$8)-ROW(D5)>=0,($F$8)-(($F$8)-ROW(D5))," ") -> 5 | E33: =IF(D33=" "," ",($E$26-$B$3*($F$8))*((D33/($F$8))-($C$18/(PI()))*SIN((PI()*D33)/($F$8)))+$B$3*D33) -> 0.10848126 | F33: =IF(D33=" "," ",(E33-E32)/(E32-E31)) -> 1.18681 | H33: =IF($F$13-ROW(H5)>=0,$F$13-($F$13-ROW(H5))," ") -> 5 | I33: =IF(H33=" "," ",($I$26-$D$3*$F$13)*((H33/$F$13)-($C$18/(PI()))*SIN((PI()*H33)/$F$13))+$D$3*H33) -> 0.10909498 | J33: =IF(H33=" "," ",(I33-I32)/(I32-I31)) -> 1.1907646 | K33: =IF($F$12-ROW(K5)>=0,$F$12-($F$12-ROW(K5))," ") -> 5 | L33: =IF(K33=" "," ",($L$26-$D$3*$F$12)*((K33/$F$12)-($C$18/(PI()))*SIN((PI()*K33)/$F$12))+$D$3*K33) -> 0.10887934 | M33: =IF(K33=" "," ",(L33-L32)/(L32-L31)) -> 1.1890463
A34: =IF(($F$9)-ROW(A6)>=0,($F$9)-(($F$9)-ROW(A6))," ") -> 6 | B34: =IF(A34=" "," ",($B$26-$B$3*($F$9))*((A34/($F$9))-($C$18/(PI()))*SIN((PI()*A34)/($F$9)))+$B$3*A34) -> 0.14246696 | C34: =IF(A34=" "," ",(B34-B33)/(B33-B32)) -> 1.1953136 | D34: =IF(($F$8)-ROW(D6)>=0,($F$8)-(($F$8)-ROW(D6))," ") -> 6 | E34: =IF(D34=" "," ",($E$26-$B$3*($F$8))*((D34/($F$8))-($C$18/(PI()))*SIN((PI()*D34)/($F$8)))+$B$3*D34) -> 0.14246696 | F34: =IF(D34=" "," ",(E34-E33)/(E33-E32)) -> 1.1953136 | H34: =IF($F$13-ROW(H6)>=0,$F$13-($F$13-ROW(H6))," ") -> 6 | I34: =IF(H34=" "," ",($I$26-$D$3*$F$13)*((H34/$F$13)-($C$18/(PI()))*SIN((PI()*H34)/$F$13))+$D$3*H34) -> 0.1435641 | J34: =IF(H34=" "," ",(I34-I33)/(I33-I32)) -> 1.1993071 | K34: =IF($F$12-ROW(K6)>=0,$F$12-($F$12-ROW(K6))," ") -> 6 | L34: =IF(K34=" "," ",($L$26-$D$3*$F$12)*((K34/$F$12)-($C$18/(PI()))*SIN((PI()*K34)/$F$12))+$D$3*K34) -> 0.143153 | M34: =IF(K34=" "," ",(L34-L33)/(L33-L32)) -> 1.19728
A35: =IF(($F$9)-ROW(A7)>=0,($F$9)-(($F$9)-ROW(A7))," ") -> 7 | B35: =IF(A35=" "," ",($B$26-$B$3*($F$9))*((A35/($F$9))-($C$18/(PI()))*SIN((PI()*A35)/($F$9)))+$B$3*A35) -> 0.18305667 | C35: =IF(A35=" "," ",(B35-B34)/(B34-B33)) -> 1.1943177 | D35: =IF(($F$8)-ROW(D7)>=0,($F$8)-(($F$8)-ROW(D7))," ") -> 7 | E35: =IF(D35=" "," ",($E$26-$B$3*($F$8))*((D35/($F$8))-($C$18/(PI()))*SIN((PI()*D35)/($F$8)))+$B$3*D35) -> 0.18305667 | F35: =IF(D35=" "," ",(E35-E34)/(E34-E33)) -> 1.1943177 | H35: =IF($F$13-ROW(H7)>=0,$F$13-($F$13-ROW(H7))," ") -> 7 | I35: =IF(H35=" "," ",($I$26-$D$3*$F$13)*((H35/$F$13)-($C$18/(PI()))*SIN((PI()*H35)/$F$13))+$D$3*H35) -> 0.18486733 | J35: =IF(H35=" "," ",(I35-I34)/(I34-I33)) -> 1.1982675 | K35: =IF($F$12-ROW(K7)>=0,$F$12-($F$12-ROW(K7))," ") -> 7 | L35: =IF(K35=" "," ",($L$26-$D$3*$F$12)*((K35/$F$12)-($C$18/(PI()))*SIN((PI()*K35)/$F$12))+$D$3*K35) -> 0.18414264 | M35: =IF(K35=" "," ",(L35-L34)/(L34-L33)) -> 1.1959517
A36: =IF(($F$9)-ROW(A8)>=0,($F$9)-(($F$9)-ROW(A8))," ") -> 8 | B36: =IF(A36=" "," ",($B$26-$B$3*($F$9))*((A36/($F$9))-($C$18/(PI()))*SIN((PI()*A36)/($F$9)))+$B$3*A36) -> 0.23126901 | C36: =IF(A36=" "," ",(B36-B35)/(B35-B34)) -> 1.1877969 | D36: =IF(($F$8)-ROW(D8)>=0,($F$8)-(($F$8)-ROW(D8))," ") -> 8 | E36: =IF(D36=" "," ",($E$26-$B$3*($F$8))*((D36/($F$8))-($C$18/(PI()))*SIN((PI()*D36)/($F$8)))+$B$3*D36) -> 0.23126901 | F36: =IF(D36=" "," ",(E36-E35)/(E35-E34)) -> 1.1877969 | H36: =IF($F$13-ROW(H8)>=0,$F$13-($F$13-ROW(H8))," ") -> 8 | I36: =IF(H36=" "," ",($I$26-$D$3*$F$13)*((H36/$F$13)-($C$18/(PI()))*SIN((PI()*H36)/$F$13))+$D$3*H36) -> 0.23408901 | J36: =IF(H36=" "," ",(I36-I35)/(I35-I34)) -> 1.1917151 | K36: =IF($F$12-ROW(K8)>=0,$F$12-($F$12-ROW(K8))," ") -> 8 | L36: =IF(K36=" "," ",($L$26-$D$3*$F$12)*((K36/$F$12)-($C$18/(PI()))*SIN((PI()*K36)/$F$12))+$D$3*K36) -> 0.23288413 | M36: =IF(K36=" "," ",(L36-L35)/(L35-L34)) -> 1.1891173
A37: =IF(($F$9)-ROW(A9)>=0,($F$9)-(($F$9)-ROW(A9))," ") -> 9 | B37: =IF(A37=" "," ",($B$26-$B$3*($F$9))*((A37/($F$9))-($C$18/(PI()))*SIN((PI()*A37)/($F$9)))+$B$3*A37) -> 0.28808544 | C37: =IF(A37=" "," ",(B37-B36)/(B36-B35)) -> 1.1784624 | D37: =IF(($F$8)-ROW(D9)>=0,($F$8)-(($F$8)-ROW(D9))," ") -> 9 | E37: =IF(D37=" "," ",($E$26-$B$3*($F$8))*((D37/($F$8))-($C$18/(PI()))*SIN((PI()*D37)/($F$8)))+$B$3*D37) -> 0.28808544 | F37: =IF(D37=" "," ",(E37-E36)/(E36-E35)) -> 1.1784624 | H37: =IF($F$13-ROW(H9)>=0,$F$13-($F$13-ROW(H9))," ") -> 9 | I37: =IF(H37=" "," ",($I$26-$D$3*$F$13)*((H37/$F$13)-($C$18/(PI()))*SIN((PI()*H37)/$F$13))+$D$3*H37) -> 0.29228858 | J37: =IF(H37=" "," ",(I37-I36)/(I36-I35)) -> 1.182397 | K37: =IF($F$12-ROW(K9)>=0,$F$12-($F$12-ROW(K9))," ") -> 9 | L37: =IF(K37=" "," ",($L$26-$D$3*$F$12)*((K37/$F$12)-($C$18/(PI()))*SIN((PI()*K37)/$F$12))+$D$3*K37) -> 0.29037557 | M37: =IF(K37=" "," ",(L37-L36)/(L36-L35)) -> 1.1795176
A38: =IF(($F$9)-ROW(A10)>=0,($F$9)-(($F$9)-ROW(A10))," ") -> 10 | B38: =IF(A38=" "," ",($B$26-$B$3*($F$9))*((A38/($F$9))-($C$18/(PI()))*SIN((PI()*A38)/($F$9)))+$B$3*A38) -> 0.3544455 | C38: =IF(A38=" "," ",(B38-B37)/(B37-B36)) -> 1.1679732 | D38: =IF(($F$8)-ROW(D10)>=0,($F$8)-(($F$8)-ROW(D10))," ") -> 10 | E38: =IF(D38=" "," ",($E$26-$B$3*($F$8))*((D38/($F$8))-($C$18/(PI()))*SIN((PI()*D38)/($F$8)))+$B$3*D38) -> 0.3544455 | F38: =IF(D38=" "," ",(E38-E37)/(E37-E36)) -> 1.1679732 | H38: =IF($F$13-ROW(H10)>=0,$F$13-($F$13-ROW(H10))," ") -> 10 | I38: =IF(H38=" "," ",($I$26-$D$3*$F$13)*((H38/$F$13)-($C$18/(PI()))*SIN((PI()*H38)/$F$13))+$D$3*H38) -> 0.36049722 | J38: =IF(H38=" "," ",(I38-I37)/(I37-I36)) -> 1.1719784 | K38: =IF($F$12-ROW(K10)>=0,$F$12-($F$12-ROW(K10))," ") -> 10 | L38: =IF(K38=" "," ",($L$26-$D$3*$F$12)*((K38/$F$12)-($C$18/(PI()))*SIN((PI()*K38)/$F$12))+$D$3*K38) -> 0.35757244 | M38: =IF(K38=" "," ",(L38-L37)/(L37-L36)) -> 1.1688152
A39: =IF(($F$9)-ROW(A11)>=0,($F$9)-(($F$9)-ROW(A11))," ") -> 11 | B39: =IF(A39=" "," ",($B$26-$B$3*($F$9))*((A39/($F$9))-($C$18/(PI()))*SIN((PI()*A39)/($F$9)))+$B$3*A39) -> 0.43124225 | C39: =IF(A39=" "," ",(B39-B38)/(B38-B37)) -> 1.1572736 | D39: =IF(($F$8)-ROW(D11)>=0,($F$8)-(($F$8)-ROW(D11))," ") -> 11 | E39: =IF(D39=" "," ",($E$26-$B$3*($F$8))*((D39/($F$8))-($C$18/(PI()))*SIN((PI()*D39)/($F$8)))+$B$3*D39) -> 0.43124225 | F39: =IF(D39=" "," ",(E39-E38)/(E38-E37)) -> 1.1572736 | H39: =IF($F$13-ROW(H11)>=0,$F$13-($F$13-ROW(H11))," ") -> 11 | I39: =IF(H39=" "," ",($I$26-$D$3*$F$13)*((H39/$F$13)-($C$18/(PI()))*SIN((PI()*H39)/$F$13))+$D$3*H39) -> 0.43971463 | J39: =IF(H39=" "," ",(I39-I38)/(I38-I37)) -> 1.1613984 | K39: =IF($F$12-ROW(K11)>=0,$F$12-($F$12-ROW(K11))," ") -> 11 | L39: =IF(K39=" "," ",($L$26-$D$3*$F$12)*((K39/$F$12)-($C$18/(PI()))*SIN((PI()*K39)/$F$12))+$D$3*K39) -> 0.43538294 | M39: =IF(K39=" "," ",(L39-L38)/(L38-L37)) -> 1.1579481
A40: =IF(($F$9)-ROW(A12)>=0,($F$9)-(($F$9)-ROW(A12))," ") -> 12 | B40: =IF(A40=" "," ",($B$26-$B$3*($F$9))*((A40/($F$9))-($C$18/(PI()))*SIN((PI()*A40)/($F$9)))+$B$3*A40) -> 0.51931789 | C40: =IF(A40=" "," ",(B40-B39)/(B39-B38)) -> 1.1468668 | D40: =IF(($F$8)-ROW(D12)>=0,($F$8)-(($F$8)-ROW(D12))," ") -> 12 | E40: =IF(D40=" "," ",($E$26-$B$3*($F$8))*((D40/($F$8))-($C$18/(PI()))*SIN((PI()*D40)/($F$8)))+$B$3*D40) -> 0.51931789 | F40: =IF(D40=" "," ",(E40-E39)/(E39-E38)) -> 1.1468668 | H40: =IF($F$13-ROW(H12)>=0,$F$13-($F$13-ROW(H12))," ") -> 12 | I40: =IF(H40=" "," ",($I$26-$D$3*$F$13)*((H40/$F$13)-($C$18/(PI()))*SIN((PI()*H40)/$F$13))+$D$3*H40) -> 0.53090585 | J40: =IF(H40=" "," ",(I40-I39)/(I39-I38)) -> 1.1511514 | K40: =IF($F$12-ROW(K12)>=0,$F$12-($F$12-ROW(K12))," ") -> 12 | L40: =IF(K40=" "," ",($L$26-$D$3*$F$12)*((K40/$F$12)-($C$18/(PI()))*SIN((PI()*K40)/$F$12))+$D$3*K40) -> 0.52466354 | M40: =IF(K40=" "," ",(L40-L39)/(L39-L38)) -> 1.1474108
A41: =IF(($F$9)-ROW(A13)>=0,($F$9)-(($F$9)-ROW(A13))," ") -> 13 | B41: =IF(A41=" "," ",($B$26-$B$3*($F$9))*((A41/($F$9))-($C$18/(PI()))*SIN((PI()*A41)/($F$9)))+$B$3*A41) -> 0.61945968 | C41: =IF(A41=" "," ",(B41-B40)/(B40-B39)) -> 1.1369975 | D41: =IF(($F$8)-ROW(D13)>=0,($F$8)-(($F$8)-ROW(D13))," ") -> 13 | E41: =IF(D41=" "," ",($E$26-$B$3*($F$8))*((D41/($F$8))-($C$18/(PI()))*SIN((PI()*D41)/($F$8)))+$B$3*D41) -> 0.61945968 | F41: =IF(D41=" "," ",(E41-E40)/(E40-E39)) -> 1.1369975 | H41: =IF($F$13-ROW(H13)>=0,$F$13-($F$13-ROW(H13))," ") -> 13 | I41: =IF(H41=" "," ",($I$26-$D$3*$F$13)*((H41/$F$13)-($C$18/(PI()))*SIN((PI()*H41)/$F$13))+$D$3*H41) -> 0.63499828 | J41: =IF(H41=" "," ",(I41-I40)/(I40-I39)) -> 1.1414741 | K41: =IF($F$12-ROW(K13)>=0,$F$12-($F$12-ROW(K13))," ") -> 13 | L41: =IF(K41=" "," ",($L$26-$D$3*$F$12)*((K41/$F$12)-($C$18/(PI()))*SIN((PI()*K41)/$F$12))+$D$3*K41) -> 0.62621484 | M41: =IF(K41=" "," ",(L41-L40)/(L40-L39)) -> 1.1374398
... A528: =IF(($F$9)-ROW(A500)>=0,($F$9)-(($F$9)-ROW(A500))," ") | B528: =IF(A528=" "," ",($B$26-$B$3*($F$9))*((A528/($F$9))-($C$18/(PI()))*SIN((PI()*A528)/($F$9)))+$B$3*A528) | C528: =IF(A528=" "," ",(B528-B527)/(B527-B526)) | D528: =IF(($F$8)-ROW(D500)>=0,($F$8)-(($F$8)-ROW(D500))," ") | E528: =IF(D528=" "," ",($E$26-$B$3*($F$8))*((D528/($F$8))-($C$18/(PI()))*SIN((PI()*D528)/($F$8)))+$B$3*D528) | F528: =IF(D528=" "," ",(E528-E527)/(E527-E526)) | H528: =IF($F$13-ROW(H500)>=0,$F$13-($F$13-ROW(H500))," ") | I528: =IF(H528=" "," ",($I$26-$D$3*$F$13)*((H528/$F$13)-($C$18/(PI()))*SIN((PI()*H528)/$F$13))+$D$3*H528) | J528: =IF(H528=" "," ",(I528-I527)/(I527-I526)) | K528: =IF($F$12-ROW(K500)>=0,$F$12-($F$12-ROW(K500))," ") | L528: =IF(K528=" "," ",($L$26-$D$3*$F$12)*((K528/$F$12)-($C$18/(PI()))*SIN((PI()*K528)/$F$12))+$D$3*K528) | M528: =IF(K528=" "," ",(L528-L527)/(L527-L526))

Sheet 2.112
A1: non-uniform-sin4 (Sin-Uniform) | F1: <-- input
J2: Re = | K2: 3900
A3: dySml = | B3: 0.0128 | C3: dzSml = | D3: 0.0128 | E3: dxSml = | F3: =D3*9 -> 0.1152 | J3: nu = | K3: =K5/K2 -> 0.00025641026 | L3: (Uinf/Re for dimensionless)
A4: GridderYc = | B4: =B7/2 -> 12 | C4: GridderZc = | D4: 12.9 | E4: GridderXc = | F4: =B15/2 -> 1.5 | J4: fluid density = | K4: 1
J5: freestream vel = | K5: 1
A7: ly = | B7: 24 | C7: lySml = | D7: 1.5104 | J7: Cf = | K7: =(2*LOG10(K2)-0.65)^-2.3 -> 0.013346704
A8: ny = | B8: =D8+F8+F9 -> 218 | C8: nySml = | D8: =D7/B3 -> 118 | E8: nyLrg1 = | F8: 50 | G8: <-- adjustable value | J8: tau = | K8: =0.5*K7*K4*K5^2 -> 0.0066733521
A9: nyLow = | B9: =F8 -> 50 | E9: nyLrg2 = | F9: 50 | G9: <-- adjustable value | J9: ufric = | K9: =SQRT(K8/K4) -> 0.081690588
A11: lz = | B11: 36 | C11: lzSml = | D11: 2.9952 | J11: y+ = | K11: =(B3*K9)/K3 -> 4.0779941
A12: nz = | B12: =D12+F13+F12 -> 346 | C12: nzSml = | D12: =D11/D3 -> 234 | E12: nzLrg1 = | F12: 50 | G12: <-- adjustable value | J12: fwall = | K12: =(1-EXP(-1*K11/25)) -> 0.15051056
A13: nzUps = | B13: =F12 -> 50 | E13: nzLrg2 = | F13: 62 | G13: <-- adjustable value
J14: Applied Dt = | K14: 0.00128
A15: lx = | B15: 3 | J15: CFL = | K15: =K14/B3 -> 0.1
A16: nx = | B16: =EVEN(B15/F3) -> 28
A18: Kuyper tune factor = | C18: 1
A20: highest ratio in y1 = | C20: =ROUND(MAX(F28:F528),3) -> 1.194 | G20: Number of cells (M) = | H20: =(B8*B12*B16)/1000000 -> 2.111984 | I20: 0.54
A21: highest ratio in y2 = | C21: =ROUND(MAX(C29:C529),3) -> 1.194
A22: highest ratio in z1 = | C22: =ROUND(MAX(M28:M528),3) -> 1.195
A23: highest ratio in z2 = | C23: =ROUND(MAX(J28:J528),3) -> 1.198
A25: y2 direction | D25: y1 direction (yLow) | H25: z2 direction | K25: z1 direction (zUps)
A26: H = | B26: =B7-(B4+D7*0.5) -> 11.2448 | D26: H = | E26: =B4-D7*0.5 -> 11.2448 | H26: H = | I26: =B11-(D4+D11*0.5) -> 21.6024 | K26: H = | L26: =D4-D11*0.5 -> 11.4024
A28: 0 | B28: =IF(A28=" "," ",($B$26-$B$3*($F$8/2))*((A28/($F$8/2))-($C$18/(PI()))*SIN((PI()*A28)/($F$8/2)))+$B$3*A28) -> 0 | D28: 0 | E28: =IF(D28=" "," ",($E$26-$B$3*($F$8))*((D28/($F$8))-($C$18/(PI()))*SIN((PI()*D28)/($F$8)))+$B$3*D28) -> 0 | H28: 0 | I28: =IF(H28=" "," ",($I$26-$D$3*$F$13)*((H28/$F$13)-($C$18/(PI()))*SIN((PI()*H28)/$F$13))+$D$3*H28) -> 0 | K28: 0 | L28: =IF(K28=" "," ",($I$26-$D$3*$F$13)*((K28/$F$13)-($C$18/(PI()))*SIN((PI()*K28)/$F$13))+$D$3*K28) -> 0
A29: =IF(($F$9)-ROW(A1)>=0,($F$9)-(($F$9)-ROW(A1))," ") -> 1 | B29: =IF(A29=" "," ",($B$26-$B$3*($F$9))*((A29/($F$9))-($C$18/(PI()))*SIN((PI()*A29)/($F$9)))+$B$3*A29) -> 0.012939526 | D29: =IF(($F$8)-ROW(D1)>=0,($F$8)-(($F$8)-ROW(D1))," ") -> 1 | E29: =IF(D29=" "," ",($E$26-$B$3*($F$8))*((D29/($F$8))-($C$18/(PI()))*SIN((PI()*D29)/($F$8)))+$B$3*D29) -> 0.012939526 | H29: =IF($F$13-ROW(H1)>=0,$F$13-($F$13-ROW(H1))," ") -> 1 | I29: =IF(H29=" "," ",($I$26-$D$3*$F$13)*((H29/$F$13)-($C$18/(PI()))*SIN((PI()*H29)/$F$13))+$D$3*H29) -> 0.012943603 | K29: =IF($F$12-ROW(K1)>=0,$F$12-($F$12-ROW(K1))," ") -> 1 | L29: =IF(K29=" "," ",($L$26-$D$3*$F$12)*((K29/$F$12)-($C$18/(PI()))*SIN((PI()*K29)/$F$12))+$D$3*K29) -> 0.0129416
A30: =IF(($F$9)-ROW(A2)>=0,($F$9)-(($F$9)-ROW(A2))," ") -> 2 | B30: =IF(A30=" "," ",($B$26-$B$3*($F$9))*((A30/($F$9))-($C$18/(PI()))*SIN((PI()*A30)/($F$9)))+$B$3*A30) -> 0.026715547 | C30: =IF(A30=" "," ",(B30-B29)/(B29-B28)) -> 1.0646465 | D30: =IF(($F$8)-ROW(D2)>=0,($F$8)-(($F$8)-ROW(D2))," ") -> 2 | E30: =IF(D30=" "," ",($E$26-$B$3*($F$8))*((D30/($F$8))-($C$18/(PI()))*SIN((PI()*D30)/($F$8)))+$B$3*D30) -> 0.026715547 | F30: =IF(D30=" "," ",(E30-E29)/(E29-E28)) -> 1.0646465 | H30: =IF($F$13-ROW(H2)>=0,$F$13-($F$13-ROW(H2))," ") -> 2 | I30: =IF(H30=" "," ",($I$26-$D$3*$F$13)*((H30/$F$13)-($C$18/(PI()))*SIN((PI()*H30)/$F$13))+$D$3*H30) -> 0.026748385 | J30: =IF(H30=" "," ",(I30-I29)/(I29-I28)) -> 1.0665331 | K30: =IF($F$12-ROW(K2)>=0,$F$12-($F$12-ROW(K2))," ") -> 2 | L30: =IF(K30=" "," ",($L$26-$D$3*$F$12)*((K30/$F$12)-($C$18/(PI()))*SIN((PI()*K30)/$F$12))+$D$3*K30) -> 0.026732126 | M30: =IF(K30=" "," ",(L30-L29)/(L29-L28)) -> 1.0655967
A31: =IF(($F$9)-ROW(A3)>=0,($F$9)-(($F$9)-ROW(A3))," ") -> 3 | B31: =IF(A31=" "," ",($B$26-$B$3*($F$9))*((A31/($F$9))-($C$18/(PI()))*SIN((PI()*A31)/($F$9)))+$B$3*A31) -> 0.042161258 | C31: =IF(A31=" "," ",(B31-B30)/(B30-B29)) -> 1.1212026 | D31: =IF(($F$8)-ROW(D3)>=0,($F$8)-(($F$8)-ROW(D3))," ") -> 3 | E31: =IF(D31=" "," ",($E$26-$B$3*($F$8))*((D31/($F$8))-($C$18/(PI()))*SIN((PI()*D31)/($F$8)))+$B$3*D31) -> 0.042161258 | F31: =IF(D31=" "," ",(E31-E30)/(E30-E29)) -> 1.1212026 | H31: =IF($F$13-ROW(H3)>=0,$F$13-($F$13-ROW(H3))," ") -> 3 | I31: =IF(H31=" "," ",($I$26-$D$3*$F$13)*((H31/$F$13)-($C$18/(PI()))*SIN((PI()*H31)/$F$13))+$D$3*H31) -> 0.042273312 | J31: =IF(H31=" "," ",(I31-I30)/(I30-I29)) -> 1.124605 | K31: =IF($F$12-ROW(K3)>=0,$F$12-($F$12-ROW(K3))," ") -> 3 | L31: =IF(K31=" "," ",($L$26-$D$3*$F$12)*((K31/$F$12)-($C$18/(PI()))*SIN((PI()*K31)/$F$12))+$D$3*K31) -> 0.042217155 | M31: =IF(K31=" "," ",(L31-L30)/(L30-L29)) -> 1.1228744
A32: =IF(($F$9)-ROW(A4)>=0,($F$9)-(($F$9)-ROW(A4))," ") -> 4 | B32: =IF(A32=" "," ",($B$26-$B$3*($F$9))*((A32/($F$9))-($C$18/(PI()))*SIN((PI()*A32)/($F$9)))+$B$3*A32) -> 0.060103263 | C32: =IF(A32=" "," ",(B32-B31)/(B31-B30)) -> 1.1616173 | D32: =IF(($F$8)-ROW(D4)>=0,($F$8)-(($F$8)-ROW(D4))," ") -> 4 | E32: =IF(D32=" "," ",($E$26-$B$3*($F$8))*((D32/($F$8))-($C$18/(PI()))*SIN((PI()*D32)/($F$8)))+$B$3*D32) -> 0.060103263 | F32: =IF(D32=" "," ",(E32-E31)/(E31-E30)) -> 1.1616173 | H32: =IF($F$13-ROW(H4)>=0,$F$13-($F$13-ROW(H4))," ") -> 4 | I32: =IF(H32=" "," ",($I$26-$D$3*$F$13)*((H32/$F$13)-($C$18/(PI()))*SIN((PI()*H32)/$F$13))+$D$3*H32) -> 0.060372936 | J32: =IF(H32=" "," ",(I32-I31)/(I31-I30)) -> 1.1658428 | K32: =IF($F$12-ROW(K4)>=0,$F$12-($F$12-ROW(K4))," ") -> 4 | L32: =IF(K32=" "," ",($L$26-$D$3*$F$12)*((K32/$F$12)-($C$18/(PI()))*SIN((PI()*K32)/$F$12))+$D$3*K32) -> 0.060235576 | M32: =IF(K32=" "," ",(L32-L31)/(L31-L30)) -> 1.1636027
A33: =IF(($F$9)-ROW(A5)>=0,($F$9)-(($F$9)-ROW(A5))," ") -> 5 | B33: =IF(A33=" "," ",($B$26-$B$3*($F$9))*((A33/($F$9))-($C$18/(PI()))*SIN((PI()*A33)/($F$9)))+$B$3*A33) -> 0.081358315 | C33: =IF(A33=" "," ",(B33-B32)/(B32-B31)) -> 1.1846531 | D33: =IF(($F$8)-ROW(D5)>=0,($F$8)-(($F$8)-ROW(D5))," ") -> 5 | E33: =IF(D33=" "," ",($E$26-$B$3*($F$8))*((D33/($F$8))-($C$18/(PI()))*SIN((PI()*D33)/($F$8)))+$B$3*D33) -> 0.081358315 | F33: =IF(D33=" "," ",(E33-E32)/(E32-E31)) -> 1.1846531 | H33: =IF($F$13-ROW(H5)>=0,$F$13-($F$13-ROW(H5))," ") -> 5 | I33: =IF(H33=" "," ",($I$26-$D$3*$F$13)*((H33/$F$13)-($C$18/(PI()))*SIN((PI()*H33)/$F$13))+$D$3*H33) -> 0.081895199 | J33: =IF(H33=" "," ",(I33-I32)/(I32-I31)) -> 1.1891 | K33: =IF($F$12-ROW(K5)>=0,$F$12-($F$12-ROW(K5))," ") -> 5 | L33: =IF(K33=" "," ",($L$26-$D$3*$F$12)*((K33/$F$12)-($C$18/(PI()))*SIN((PI()*K33)/$F$12))+$D$3*K33) -> 0.08161628 | M33: =IF(K33=" "," ",(L33-L32)/(L32-L31)) -> 1.1866025
A34: =IF(($F$9)-ROW(A6)>=0,($F$9)-(($F$9)-ROW(A6))," ") -> 6 | B34: =IF(A34=" "," ",($B$26-$B$3*($F$9))*((A34/($F$9))-($C$18/(PI()))*SIN((PI()*A34)/($F$9)))+$B$3*A34) -> 0.10673009 | C34: =IF(A34=" "," ",(B34-B33)/(B33-B32)) -> 1.1936822 | D34: =IF(($F$8)-ROW(D6)>=0,($F$8)-(($F$8)-ROW(D6))," ") -> 6 | E34: =IF(D34=" "," ",($E$26-$B$3*($F$8))*((D34/($F$8))-($C$18/(PI()))*SIN((PI()*D34)/($F$8)))+$B$3*D34) -> 0.10673009 | F34: =IF(D34=" "," ",(E34-E33)/(E33-E32)) -> 1.1936822 | H34: =IF($F$13-ROW(H6)>=0,$F$13-($F$13-ROW(H6))," ") -> 6 | I34: =IF(H34=" "," ",($I$26-$D$3*$F$13)*((H34/$F$13)-($C$18/(PI()))*SIN((PI()*H34)/$F$13))+$D$3*H34) -> 0.10767926 | J34: =IF(H34=" "," ",(I34-I33)/(I33-I32)) -> 1.198018 | K34: =IF($F$12-ROW(K6)>=0,$F$12-($F$12-ROW(K6))," ") -> 6 | L34: =IF(K34=" "," ",($L$26-$D$3*$F$12)*((K34/$F$12)-($C$18/(PI()))*SIN((PI()*K34)/$F$12))+$D$3*K34) -> 0.10717489 | M34: =IF(K34=" "," ",(L34-L33)/(L33-L32)) -> 1.1954054
A35: =IF(($F$9)-ROW(A7)>=0,($F$9)-(($F$9)-ROW(A7))," ") -> 7 | B35: =IF(A35=" "," ",($B$26-$B$3*($F$9))*((A35/($F$9))-($C$18/(PI()))*SIN((PI()*A35)/($F$9)))+$B$3*A35) -> 0.13700602 | C35: =IF(A35=" "," ",(B35-B34)/(B34-B33)) -> 1.1932918 | D35: =IF(($F$8)-ROW(D7)>=0,($F$8)-(($F$8)-ROW(D7))," ") -> 7 | E35: =IF(D35=" "," ",($E$26-$B$3*($F$8))*((D35/($F$8))-($C$18/(PI()))*SIN((PI()*D35)/($F$8)))+$B$3*D35) -> 0.13700602 | F35: =IF(D35=" "," ",(E35-E34)/(E34-E33)) -> 1.1932918 | H35: =IF($F$13-ROW(H7)>=0,$F$13-($F$13-ROW(H7))," ") -> 7 | I35: =IF(H35=" "," ",($I$26-$D$3*$F$13)*((H35/$F$13)-($C$18/(PI()))*SIN((PI()*H35)/$F$13))+$D$3*H35) -> 0.13855333 | J35: =IF(H35=" "," ",(I35-I34)/(I34-I33)) -> 1.1974093 | K35: =IF($F$12-ROW(K7)>=0,$F$12-($F$12-ROW(K7))," ") -> 7 | L35: =IF(K35=" "," ",($L$26-$D$3*$F$12)*((K35/$F$12)-($C$18/(PI()))*SIN((PI()*K35)/$F$12))+$D$3*K35) -> 0.13771053 | M35: =IF(K35=" "," ",(L35-L34)/(L34-L33)) -> 1.1947304
